Workbook

Sheet Sheet1
A1: S.No | B1: Cluster | C1: Lattitude | D1: Longtitude | E1: Location address | F1: Crack/Pothole | G1: Type | H1: Depth | I1: Width | J1: Severity | K1: Rating | L1: Cost of repairing | M1: Image
A2: 1 | B2: 1 | C2: 39.162998 | D2: -123.63914 | E2: Philo,CA,95466,USA | F2: Pothole | G2: Pothole | H2: =VLOOKUP(M2,Sheet2!$B$3:$D$47,3,0) -> 3 | I2: =VLOOKUP(M2,Sheet2!$B$3:$C$47,2,0) -> 24 | J2: Low | K2: P3 | L2: 80 | M2: potholes58.jpg
A3: 3 | B3: 1 | C3: 39.157254 | D3: -123.63078 | E3: Philo,CA,95466,USA | F3: Crack | G3: Alligator Crack | H3: =VLOOKUP(M3,Sheet2!$B$3:$D$47,3,0) -> 2.5 | I3: =VLOOKUP(M3,Sheet2!$B$3:$C$47,2,0) -> 18 | J3: Medium | K3: P2 | L3: 225 | M3: 6321.jpg
A4: 4 | B4: 1 | C4: 39.156339 | D4: -123.625136 | E4: Philo,CA,95466,USA | F4: Pothole | G4: Pothole | H4: =VLOOKUP(M4,Sheet2!$B$3:$D$47,3,0) -> 7 | I4: =VLOOKUP(M4,Sheet2!$B$3:$C$47,2,0) -> 42 | J4: Medium | K4: P2 | L4: 334.25 | M4: potholes574.jpg
A5: 5 | B5: 1 | C5: 39.155615 | D5: -123.62346 | E5: Philo,CA,95466,USA | F5: Pothole | G5: Pothole | H5: =VLOOKUP(M5,Sheet2!$B$3:$D$47,3,0) -> 4 | I5: =VLOOKUP(M5,Sheet2!$B$3:$C$47,2,0) -> 30 | J5: Low | K5: P3 | L5: 105 | M5: potholes573.jpg
A6: 6 | B6: 1 | C6: 39.155116 | D6: -123.62217 | E6: Philo,CA,95466,USA | F6: Pothole | G6: Pothole | H6: =VLOOKUP(M6,Sheet2!$B$3:$D$47,3,0) -> 4 | I6: =VLOOKUP(M6,Sheet2!$B$3:$C$47,2,0) -> 24 | J6: Low | K6: P3 | L6: 157 | M6: potholes571.jpg
A7: 8 | B7: 2 | C7: 39.864034 | D7: -122.20028 | E7: West Side Highway | F7: Crack | G7: Alligator Crack | H7: =VLOOKUP(M7,Sheet2!$B$3:$D$47,3,0) -> 3 | I7: =VLOOKUP(M7,Sheet2!$B$3:$C$47,2,0) -> 20 | J7: High | K7: P1 | L7: 480 | M7: 631.jpg
A8: 9 | B8: 2 | C8: 39.84967 | D8: -122.20026 | E8: West Side Highway | F8: Crack | G8: Horizontal Crack | H8: =VLOOKUP(M8,Sheet2!$B$3:$D$47,3,0) -> 2.5 | I8: =VLOOKUP(M8,Sheet2!$B$3:$C$47,2,0) -> 16 | J8: High | K8: P1 | L8: 489.75 | M8: 628.jpg
A9: 10 | B9: 2 | C9: 39.791059 | D9: -122.20311 | E9: West Side Highway | F9: Crack | G9: Alligator Crack | H9: =VLOOKUP(M9,Sheet2!$B$3:$D$47,3,0) -> 2 | I9: =VLOOKUP(M9,Sheet2!$B$3:$C$47,2,0) -> 18 | J9: High | K9: P1 | L9: 180.75 | M9: 625.jpg
A10: 11 | B10: 2 | C10: 39.785597 | D10: -122.204449 | E10: West Side Highway | F10: Bin | G10: Trashcan | H10: NA | I10: NA | J10: High | K10: P1 | L10: 150 | M10: Trash1.jpg
A11: 12 | B11: 2 | C11: 39.783846 | D11: -122.20454 | E11: West Side Highway | F11: Damaged Paint | G11: Damage Paint | H11: 5 | I11: 3 | J11: Medium | K11: P2 | L11: 232.5 | M11: damage_paint3.jpg
A12: 13 | B12: 2 | C12: 39.78042 | D12: -122.20471 | E12: West Side Highway | F12: Manhole | G12: Manhole | H12: NA | I12: NA | J12: High | K12: P1 | L12: 150 | M12: 1123.jpg
A13: 15 | B13: 3 | C13: 39.732551 | D13: -121.82443 | E13: Golden State highway | F13: Pothole | G13: Pothole | H13: 6 | I13: 39 | J13: Medium | K13: P2 | L13: 343.25 | M13: potholes57.jpg
A14: 16 | B14: 3 | C14: 39.733347 | D14: -121.82323 | E14: Golden State highway | F14: Pothole | G14: Pothole | H14: =VLOOKUP(M14,Sheet2!$B$3:$D$47,3,0) -> 6 | I14: =VLOOKUP(M14,Sheet2!$B$3:$C$47,2,0) -> 48 | J14: Medium | K14: P2 | L14: 392 | M14: potholes568.jpg
A15: 17 | B15: 3 | C15: 39.735389 | D15: -121.8201 | E15: Golden State highway | F15: Pothole | G15: Pothole | H15: =VLOOKUP(M15,Sheet2!$B$3:$D$47,3,0) -> 4 | I15: =VLOOKUP(M15,Sheet2!$B$3:$C$47,2,0) -> 30 | J15: Low | K15: P3 | L15: 189 | M15: potholes567.jpg
A16: 18 | B16: 3 | C16: 39.73517 | D16: -121.818286 | E16: Golden State highway | F16: Pothole | G16: Pothole | H16: =VLOOKUP(M16,Sheet2!$B$3:$D$47,3,0) -> 5 | I16: =VLOOKUP(M16,Sheet2!$B$3:$C$47,2,0) -> 24 | J16: Low | K16: P3 | L16: 203 | M16: potholes566.jpg
A17: 19 | B17: 3 | C17: 39.734518 | D17: -121.81725 | E17: Golden State highway | F17: Crack | G17: Horizontal Crack | H17: =VLOOKUP(M17,Sheet2!$B$3:$D$47,3,0) -> 1.5 | I17: =VLOOKUP(M17,Sheet2!$B$3:$C$47,2,0) -> 12 | J17: Negligible | K17: P4 | L17: 129.5 | M17: 622.png
A18: 20 | B18: 3 | C18: 39.733598 | D18: -121.81593 | E18: Golden State highway | F18: Crack | G18: Alligator Crack | H18: =VLOOKUP(M18,Sheet2!$B$3:$D$47,3,0) -> 2 | I18: =VLOOKUP(M18,Sheet2!$B$3:$C$47,2,0) -> 14 | J18: Negligible | K18: P4 | L18: 103 | M18: 617.jpg
A19: 21 | B19: 3 | C19: 39.731692 | D19: -121.81378 | E19: Golden State highway | F19: Crack | G19: Horizontal Crack | H19: =VLOOKUP(M19,Sheet2!$B$3:$D$47,3,0) -> 3 | I19: =VLOOKUP(M19,Sheet2!$B$3:$C$47,2,0) -> 22 | J19: Negligible | K19: P4 | L19: 126 | M19: 615.jpg
A20: 22 | B20: 4 | C20: 39.774744 | D20: -123.24828 | E20: Covela RD, CA,95428, USA | F20: Pothole | G20: Pothole | H20: =VLOOKUP(M20,Sheet2!$B$3:$D$47,3,0) -> 6 | I20: =VLOOKUP(M20,Sheet2!$B$3:$C$47,2,0) -> 36 | J20: Medium | K20: P2 | L20: 382.25 | M20: potholes565.jpg
A21: 23 | B21: 4 | C21: 39.779881 | D21: -123.24828 | E21: Covela RD, CA,95428, USA | F21: Pothole | G21: Pothole | H21: =VLOOKUP(M21,Sheet2!$B$3:$D$47,3,0) -> 4 | I21: =VLOOKUP(M21,Sheet2!$B$3:$C$47,2,0) -> 36 | J21: Medium | K21: P2 | L21: 344.75 | M21: potholes564.jpg
A22: 24 | B22: 4 | C22: 39.784871 | D22: -123.24834 | E22: Covela RD, CA,95428, USA | F22: Pothole | G22: Pothole | H22: =VLOOKUP(M22,Sheet2!$B$3:$D$47,3,0) -> 5 | I22: =VLOOKUP(M22,Sheet2!$B$3:$C$47,2,0) -> 36 | J22: Medium | K22: P2 | L22: 393.5 | M22: potholes559.jpg
A23: 25 | B23: 4 | C23: 39.792123 | D23: -123.24822 | E23: Covela RD, CA,95428, USA | F23: Pothole | G23: Pothole | H23: =VLOOKUP(M23,Sheet2!$B$3:$D$47,3,0) -> 4 | I23: =VLOOKUP(M23,Sheet2!$B$3:$C$47,2,0) -> 30 | J23: Low | K23: P3 | L23: 176 | M23: potholes558.jpg
A24: 26 | B24: 4 | C24: 39.813646 | D24: -123.24816 | E24: Covela RD, CA,95428, USA | F24: Crack | G24: Alligator Crack | H24: =VLOOKUP(M24,Sheet2!$B$3:$D$47,3,0) -> 3 | I24: =VLOOKUP(M24,Sheet2!$B$3:$C$47,2,0) -> 24 | J24: High | K24: P1 | L24: 470.25 | M24: 618.jpg
A25: 27 | B25: 4 | C25: 39.817026 | D25: -123.24419 | E25: Covela RD, CA,95428, USA | F25: Crack | G25: Alligator Crack | H25: =VLOOKUP(M25,Sheet2!$B$3:$D$47,3,0) -> 2.5 | I25: =VLOOKUP(M25,Sheet2!$B$3:$C$47,2,0) -> 16 | J25: High | K25: P1 | L25: 472.5 | M25: 613.jpg
A26: 29 | B26: 5 | C26: 36.923046 | D26: -119.8876 | E26: Madera, CA 93636,USA | F26: Pothole | G26: Pothole | H26: =VLOOKUP(M26,Sheet2!$B$3:$D$47,3,0) -> 5 | I26: =VLOOKUP(M26,Sheet2!$B$3:$C$47,2,0) -> 54 | J26: High | K26: P1 | L26: 470.25 | M26: potholes551.jpg
A27: 30 | B27: 5 | C27: 36.923108 | D27: -119.85738 | E27: Madera, CA 93636,USA | F27: Pothole | G27: Pothole | H27: =VLOOKUP(M27,Sheet2!$B$3:$D$47,3,0) -> 5 | I27: =VLOOKUP(M27,Sheet2!$B$3:$C$47,2,0) -> 48 | J27: Medium | K27: P2 | L27: 356.75 | M27: potholes550.jpg
A28: 32 | B28: 5 | C28: 36.923291 | D28: -119.79441 | E28: Madera, CA 93636,USA | F28: Crack | G28: Alligator Crack | H28: =VLOOKUP(M28,Sheet2!$B$3:$D$47,3,0) -> 2 | I28: =VLOOKUP(M28,Sheet2!$B$3:$C$47,2,0) -> 18 | J28: Low | K28: P3 | L28: 127 | M28: 611.jpg
... A30: 34 | B30: 5 | C30: 36.909622 | D30: -119.7927 | E30: Madera, CA 93636,USA | F30: Crack | G30: Alligator Crack | H30: =VLOOKUP(M30,Sheet2!$B$3:$D$47,3,0) -> 3 | I30: =VLOOKUP(M30,Sheet2!$B$3:$C$47,2,0) -> 20 | J30: Low | K30: P3 | L30: 173 | M30: 602.jpg
A31: 35 | B31: 5 | C31: 36.906541 | D31: -119.79252 | E31: Madera, CA 93636,USA | F31: Bin | G31: Trashcan | H31: NA | I31: NA | J31: Low | K31: P3 | L31: 150 | M31: Trash3.jpg
A32: 36 | B32: 6 | C32: 37.303842 | D32: -120.49298 | E32: Merced,California,95340,USA | F32: Damaged Paint | G32: Damage Paint | H32: 5 | I32: 3 | J32: Medium | K32: P2 | L32: 232.5 | M32: fadded_paint2.jpg
A33: 37 | B33: 6 | C33: 37.306044 | D33: -120.49169 | E33: Merced,California,95340,USA | F33: Manhole | G33: Manhole | H33: NA | I33: NA | J33: Medium | K33: P2 | L33: 150 | M33: 1122.jpg
A34: 38 | B34: 6 | C34: 37.309505 | D34: -120.48967 | E34: Merced,California,95340,USA | F34: Pothole | G34: Pothole | H34: =VLOOKUP(M34,Sheet2!$B$3:$D$47,3,0) -> 6 | I34: =VLOOKUP(M34,Sheet2!$B$3:$C$47,2,0) -> 40 | J34: Medium | K34: P2 | L34: 342.5 | M34: 548.jpg
A35: 39 | B35: 6 | C35: 37.311575 | D35: -120.48854 | E35: Merced,California,95340,USA | F35: Pothole | G35: Pothole | H35: =VLOOKUP(M35,Sheet2!$B$3:$D$47,3,0) -> 3 | I35: =VLOOKUP(M35,Sheet2!$B$3:$C$47,2,0) -> 145 | J35: High | K35: P1 | L35: 474.75 | M35: 547.webp
A36: 40 | B36: 6 | C36: 37.313726 | D36: -120.48746 | E36: Merced,California,95340,USA | F36: Pothole | G36: Pothole | H36: =VLOOKUP(M36,Sheet2!$B$3:$D$47,3,0) -> 5 | I36: =VLOOKUP(M36,Sheet2!$B$3:$C$47,2,0) -> 50 | J36: High | K36: P1 | L36: 484.5 | M36: 546.jpg
A37: 41 | B37: 6 | C37: 37.313949 | D37: -120.48865 | E37: Merced,California,95340,USA | F37: Pothole | G37: Pothole | H37: =VLOOKUP(M37,Sheet2!$B$3:$D$47,3,0) -> 4 | I37: =VLOOKUP(M37,Sheet2!$B$3:$C$47,2,0) -> 55 | J37: High | K37: P1 | L37: 475.5 | M37: 545.webp
A38: 42 | B38: 6 | C38: 37.314964 | D38: -120.49201 | E38: Merced,California,95340,USA | F38: Pothole | G38: Pothole | H38: =VLOOKUP(M38,Sheet2!$B$3:$D$47,3,0) -> 6 | I38: =VLOOKUP(M38,Sheet2!$B$3:$C$47,2,0) -> 48 | J38: Medium | K38: P2 | L38: 334.25 | M38: potholes598.jpg
A39: 45 | B39: 7 | C39: 37.467 | D39: -120.81531 | E39: Lomita Park, San Mateo | F39: Crack | G39: Horizontal Crack | H39: =VLOOKUP(M39,Sheet2!$B$3:$D$47,3,0) -> 1.5 | I39: =VLOOKUP(M39,Sheet2!$B$3:$C$47,2,0) -> 12 | J39: Medium | K39: P2 | L39: 278.5 | M39: 585.jpg
A40: 46 | B40: 7 | C40: 37.466585 | D40: -120.81477 | E40: Lomita Park, San Mateo | F40: Pothole | G40: Pothole | H40: =VLOOKUP(M40,Sheet2!$B$3:$D$47,3,0) -> 5 | I40: =VLOOKUP(M40,Sheet2!$B$3:$C$47,2,0) -> 27 | J40: Low | K40: P3 | L40: 83 | M40: 130.jpg
A41: 47 | B41: 7 | C41: 37.466561 | D41: -120.81434 | E41: Lomita Park, San Mateo | F41: Pothole | G41: Pothole | H41: =VLOOKUP(M41,Sheet2!$B$3:$D$47,3,0) -> 6 | I41: =VLOOKUP(M41,Sheet2!$B$3:$C$47,2,0) -> 26 | J41: Low | K41: P3 | L41: 173 | M41: 129.jpg
...

Sheet Sheet2
B2: Image | C2: Width (approx) | D2: Depth (approx) | E2: Notes
B3: 126.jpg | C3: 22 | D3: 5 | E3: Clean, dry, circular pothole in center of road
B4: 129.jpg | C4: 26 | D4: 6 | E4: Water-filled with loose gravel
B5: 130.jpg | C5: 27 | D5: 5 | E5: Water-filled, near intersection
B6: 540.jpg | C6: 75 | D6: 6 | E6: Long trench near roadside curb
B7: 541.jpg | C7: 120 | D7: 6 | E7: Cluster of multiple potholes
B8: 544.webp | C8: 170 | D8: 4 | E8: Severely worn road with multiple pothole patches
B9: 545.webp | C9: 55 | D9: 4 | E9: Irregular, edge-of-road wear
B10: 546.jpg | C10: 50 | D10: 5 | E10: Busy urban intersection pothole
B11: 547.webp | C11: 145 | D11: 3 | E11: City road with pothole clusters
B12: 548.jpg | C12: 40 | D12: 6 | E12: Deep water-filled pothole near shoulder
B13: potholes565.jpg | C13: 36 | D13: 6
B14: potholes566.jpg | C14: 24 | D14: 5
B15: potholes567.jpg | C15: 30 | D15: 4
B16: potholes568.jpg | C16: 48 | D16: 6
B17: potholes570.jpg | C17: 36 | D17: 5
B18: potholes571.jpg | C18: 24 | D18: 4
B19: potholes573.jpg | C19: 30 | D19: 4
B20: potholes574.jpg | C20: 42 | D20: 7
B21: potholes598.jpg | C21: 48 | D21: 6
B22: potholes57.webp | C22: 30 | D22: 4
B23: potholes58.jpg | C23: 24 | D23: 3
B24: potholes539.jpg | C24: 36 | D24: 4
... B47: 6321.jpg | C47: 18 | D47: 2.5
